Workbook

Sheet Sheet1
A3: Row Labels | B3: Average of csat_score | C3: Average of nps_score | D3: Average of resolution_numeric
A4: DIRECT | B4: 4 | C4: 9.3333333 | D4: 2.4814815
A5: RAG | B5: 4.3658537 | C5: 9.097561 | D5: 2.3170732
A6: Grand Total | B6: 4.2205882 | C6: 9.1911765 | D6: 2.3823529
A9: Row Labels | B9: Sum of Total | C9: Sum of Surveys
A10: DIRECT | B10: 164 | C10: 27
A11: RAG | B11: 175 | C11: 41
A12: Grand Total | B12: 339 | C12: 68 | D12: =C12/B12 -> 0.20058997

Sheet chatbot_sessions_raw
A1: session_id | B1: user_id | C1: created_at | D1: session_mode | E1: session_use_rag | F1: interaction_number | G1: timestamp | H1: query | I1: routed_query | J1: mode | K1: use_rag | L1: used_cache | M1: latency_min | N1: results_count | O1: title_response | P1: score_response | Q1: csat_score | R1: nps_score | S1: resolution_numeric | T1: csat_category | U1: nps_category | V1: resolution_label | W1: Total | X1: Surveys
A2: 40cf9414-6b0c-4b55-a80f-7e205d1fcf91 | B2: 57 312 5489784 | C2: 46134 | D2: RAG | E2: TRUE | F2: 1 | G2: 0.80277778 | H2: Películas de comedia divertidas | I2: Películas de comedia divertidas | J2: RAG | K2: TRUE | L2: FALSE | M2: 16.80805 | N2: 5 | O2: Pelé: Birth of a Legend | P2: 0.0548 | Q2: 2 | R2: 3 | S2: 1 | T2: =_xlfn.XLOOKUP(Table1[[#This Row],[csat_score]],Sheet2!A:A,Sheet2!D:D) -> Baja | U2: =_xlfn.XLOOKUP(Table1[[#This Row],[nps_score]],Sheet2!B:B,Sheet2!E:E) -> detractor | V2: =_xlfn.XLOOKUP(Table1[[#This Row],[resolution_numeric]],Sheet2!C:C,Sheet2!F:F) -> no | W2: =1 -> 1 | X2: =IF(ISBLANK(Table1[[#This Row],[nps_category]]),0,1) -> 1
A3: cd7d7ecd-83f1-4ba5-8adb-9c26f84632dd | B3: 57 317 8517661 | C3: 46131 | D3: RAG | E3: TRUE | F3: 1 | G3: 0.11041667 | H3: recomienda me novelas como sin senos si hay paraíso | I3: recomienda me novelas como sin senos si hay paraíso | J3: RAG | K3: TRUE | L3: FALSE | M3: 2.4817167 | N3: 5 | O3: Trilussa - Storia d'amore e di poesia | P3: 0.1342 | Q3: 5 | R3: 7 | S3: 1 | T3: =_xlfn.XLOOKUP(Table1[[#This Row],[csat_score]],Sheet2!A:A,Sheet2!D:D) -> Alta | U3: =_xlfn.XLOOKUP(Table1[[#This Row],[nps_score]],Sheet2!B:B,Sheet2!E:E) -> passive | V3: =_xlfn.XLOOKUP(Table1[[#This Row],[resolution_numeric]],Sheet2!C:C,Sheet2!F:F) -> no | W3: =1 -> 1 | X3: =IF(ISBLANK(Table1[[#This Row],[nps_category]]),0,1) -> 1
A4: cd7d7ecd-83f1-4ba5-8adb-9c26f84632dd | B4: 57 317 8517661 | C4: 46131 | D4: RAG | E4: TRUE | F4: 2 | G4: 0.11458333 | H4: una novela que sea de colombia | I4: una novela que sea de colombia | J4: RAG | K4: TRUE | L4: FALSE | M4: 1.96285 | N4: 5 | O4: El Señor de los Cielos | P4: 0.2524 | Q4: 5 | R4: 7 | S4: 1 | T4: =_xlfn.XLOOKUP(Table1[[#This Row],[csat_score]],Sheet2!A:A,Sheet2!D:D) -> Alta | U4: =_xlfn.XLOOKUP(Table1[[#This Row],[nps_score]],Sheet2!B:B,Sheet2!E:E) -> passive | V4: =_xlfn.XLOOKUP(Table1[[#This Row],[resolution_numeric]],Sheet2!C:C,Sheet2!F:F) -> no | W4: =1 -> 1 | X4: =IF(ISBLANK(Table1[[#This Row],[nps_category]]),0,1) -> 1
A5: cd7d7ecd-83f1-4ba5-8adb-9c26f84632dd | B5: 57 317 8517661 | C5: 46131 | D5: RAG | E5: TRUE | F5: 3 | G5: 0.11875 | H5: y series de colombia como sin senos si hay paraíso o el man es german | I5: y series de colombia como sin senos si hay paraíso o el man es german | J5: RAG | K5: TRUE | L5: FALSE | M5: 1.6333 | N5: 5 | O5: Juanpis González - The Series | P5: 0.3509 | Q5: 5 | R5: 7 | S5: 1 | T5: =_xlfn.XLOOKUP(Table1[[#This Row],[csat_score]],Sheet2!A:A,Sheet2!D:D) -> Alta | U5: =_xlfn.XLOOKUP(Table1[[#This Row],[nps_score]],Sheet2!B:B,Sheet2!E:E) -> passive | V5: =_xlfn.XLOOKUP(Table1[[#This Row],[resolution_numeric]],Sheet2!C:C,Sheet2!F:F) -> no | W5: =1 -> 1 | X5: =IF(ISBLANK(Table1[[#This Row],[nps_category]]),0,1) -> 1
A6: cd7d7ecd-83f1-4ba5-8adb-9c26f84632dd | B6: 57 317 8517661 | C6: 46131 | D6: RAG | E6: TRUE | F6: 4 | G6: 0.12986111 | H6: y una parecida a la reina del flow | I6: y una parecida a la reina del flow | J6: RAG | K6: TRUE | L6: FALSE | M6: 5.5396667 | N6: 5 | O6: Flow | P6: 0.2484 | Q6: 5 | R6: 7 | S6: 1 | T6: =_xlfn.XLOOKUP(Table1[[#This Row],[csat_score]],Sheet2!A:A,Sheet2!D:D) -> Alta | U6: =_xlfn.XLOOKUP(Table1[[#This Row],[nps_score]],Sheet2!B:B,Sheet2!E:E) -> passive | V6: =_xlfn.XLOOKUP(Table1[[#This Row],[resolution_numeric]],Sheet2!C:C,Sheet2!F:F) -> no | W6: =1 -> 1 | X6: =IF(ISBLANK(Table1[[#This Row],[nps_category]]),0,1) -> 1
A7: d838cc06-a4eb-43cb-87cf-aa38d98490d3 | B7: 57 310 7677418 | C7: 46131 | D7: DIRECT | E7: FALSE | F7: 1 | G7: 0.10694444 | H7: lista de películas de acción mas vistas | I7: lista de películas de acción mas vistas | J7: DIRECT | K7: FALSE | L7: FALSE | M7: 1.2540167 | N7: 5 | O7: Cabrujas en el país del disimulo | P7: 0.1434 | Q7: 3 | R7: 7 | S7: 2 | T7: =_xlfn.XLOOKUP(Table1[[#This Row],[csat_score]],Sheet2!A:A,Sheet2!D:D) -> Media | U7: =_xlfn.XLOOKUP(Table1[[#This Row],[nps_score]],Sheet2!B:B,Sheet2!E:E) -> passive | V7: =_xlfn.XLOOKUP(Table1[[#This Row],[resolution_numeric]],Sheet2!C:C,Sheet2!F:F) -> partial | W7: =1 -> 1 | X7: =IF(ISBLANK(Table1[[#This Row],[nps_category]]),0,1) -> 1
A8: d838cc06-a4eb-43cb-87cf-aa38d98490d3 | B8: 57 310 7677418 | C8: 46131 | D8: DIRECT | E8: FALSE | F8: 2 | G8: 0.11111111 | H8: mejores películas de ciencia ficción | I8: mejores películas de ciencia ficción | J8: DIRECT | K8: FALSE | L8: FALSE | M8: 3.649 | N8: 5 | O8: Cristóbal Balenciaga | P8: 0.102 | Q8: 3 | R8: 7 | S8: 2 | T8: =_xlfn.XLOOKUP(Table1[[#This Row],[csat_score]],Sheet2!A:A,Sheet2!D:D) -> Media | U8: =_xlfn.XLOOKUP(Table1[[#This Row],[nps_score]],Sheet2!B:B,Sheet2!E:E) -> passive | V8: =_xlfn.XLOOKUP(Table1[[#This Row],[resolution_numeric]],Sheet2!C:C,Sheet2!F:F) -> partial | W8: =1 -> 1 | X8: =IF(ISBLANK(Table1[[#This Row],[nps_category]]),0,1) -> 1
A9: d838cc06-a4eb-43cb-87cf-aa38d98490d3 | B9: 57 310 7677418 | C9: 46131 | D9: DIRECT | E9: FALSE | F9: 3 | G9: 0.12430556 | H9: si | I9: si | J9: DIRECT | K9: FALSE | L9: FALSE | M9: 7.1902667 | N9: 5 | O9: Total DramaRama | P9: 0.2473 | Q9: 3 | R9: 7 | S9: 2 | T9: =_xlfn.XLOOKUP(Table1[[#This Row],[csat_score]],Sheet2!A:A,Sheet2!D:D) -> Media | U9: =_xlfn.XLOOKUP(Table1[[#This Row],[nps_score]],Sheet2!B:B,Sheet2!E:E) -> passive | V9: =_xlfn.XLOOKUP(Table1[[#This Row],[resolution_numeric]],Sheet2!C:C,Sheet2!F:F) -> partial | W9: =1 -> 1 | X9: =IF(ISBLANK(Table1[[#This Row],[nps_category]]),0,1) -> 1
A10: d838cc06-a4eb-43cb-87cf-aa38d98490d3 | B10: 57 310 7677418 | C10: 46131 | D10: DIRECT | E10: FALSE | F10: 4 | G10: 0.12638889 | H10: drama | I10: drama | J10: DIRECT | K10: FALSE | L10: FALSE | M10: 1.17795 | N10: 5 | O10: Yudh | P10: 0.3613 | Q10: 3 | R10: 7 | S10: 2 | T10: =_xlfn.XLOOKUP(Table1[[#This Row],[csat_score]],Sheet2!A:A,Sheet2!D:D) -> Media | U10: =_xlfn.XLOOKUP(Table1[[#This Row],[nps_score]],Sheet2!B:B,Sheet2!E:E) -> passive | V10: =_xlfn.XLOOKUP(Table1[[#This Row],[resolution_numeric]],Sheet2!C:C,Sheet2!F:F) -> partial | W10: =1 -> 1 | X10: =IF(ISBLANK(Table1[[#This Row],[nps_category]]),0,1) -> 1
A11: 18bac071-cac8-47d5-9bec-1b746953859f | B11: 57 302 5203977 | C11: 46134 | D11: RAG | E11: TRUE | F11: 1 | G11: 0.92916667 | H11: recomienda algo parecido a harry potte | I11: recomienda algo parecido a harry potte | J11: RAG | K11: TRUE | L11: FALSE | M11: 18.966117 | N11: 5 | O11: Harry Potter: Wizards of Baking | P11: 0.3658 | Q11: 3 | R11: 7 | S11: 2 | T11: =_xlfn.XLOOKUP(Table1[[#This Row],[csat_score]],Sheet2!A:A,Sheet2!D:D) -> Media | U11: =_xlfn.XLOOKUP(Table1[[#This Row],[nps_score]],Sheet2!B:B,Sheet2!E:E) -> passive | V11: =_xlfn.XLOOKUP(Table1[[#This Row],[resolution_numeric]],Sheet2!C:C,Sheet2!F:F) -> partial | W11: =1 -> 1 | X11: =IF(ISBLANK(Table1[[#This Row],[nps_category]]),0,1) -> 1
A12: 18bac071-cac8-47d5-9bec-1b746953859f | B12: 57 302 5203977 | C12: 46134 | D12: RAG | E12: TRUE | F12: 2 | G12: 0.94236111 | H12: no gracias asi esta bien | I12: no gracias asi esta bien | J12: RAG | K12: TRUE | L12: FALSE | M12: 6.933 | N12: 5 | O12: Así es la vida | P12: 0.1832 | Q12: 3 | R12: 7 | S12: 2 | T12: =_xlfn.XLOOKUP(Table1[[#This Row],[csat_score]],Sheet2!A:A,Sheet2!D:D) -> Media | U12: =_xlfn.XLOOKUP(Table1[[#This Row],[nps_score]],Sheet2!B:B,Sheet2!E:E) -> passive | V12: =_xlfn.XLOOKUP(Table1[[#This Row],[resolution_numeric]],Sheet2!C:C,Sheet2!F:F) -> partial | W12: =1 -> 1 | X12: =IF(ISBLANK(Table1[[#This Row],[nps_category]]),0,1) -> 1
A13: 695cd73f-1759-4d9d-afda-d0c12ab6d2a8 | B13: 57 301 5989061 | C13: 46134 | D13: DIRECT | E13: FALSE | F13: 2 | G13: 0.70416667 | H13: una peli sobre un robo millonario | I13: una peli sobre un robo millonario | J13: DIRECT | K13: FALSE | L13: FALSE | M13: 10.170367 | N13: 5 | O13: Romário, o Cara | P13: 0.1605 | Q13: 5 | R13: 7 | S13: 2 | T13: =_xlfn.XLOOKUP(Table1[[#This Row],[csat_score]],Sheet2!A:A,Sheet2!D:D) -> Alta | U13: =_xlfn.XLOOKUP(Table1[[#This Row],[nps_score]],Sheet2!B:B,Sheet2!E:E) -> passive | V13: =_xlfn.XLOOKUP(Table1[[#This Row],[resolution_numeric]],Sheet2!C:C,Sheet2!F:F) -> partial | W13: =1 -> 1 | X13: =IF(ISBLANK(Table1[[#This Row],[nps_category]]),0,1) -> 1
... A52: c5ff782e-a3d3-42d0-aa73-580ec74e9ac8 | B52: 57 317 8517661 | C52: 46139 | D52: RAG | E52: TRUE | F52: 1 | G52: 0.055555556 | H52: serie como diario de vampiros | I52: serie como diario de vampiros | J52: RAG | K52: TRUE | L52: FALSE | M52: 8.5480833 | N52: 5 | O52: Mama Drama | P52: 0.4149 | Q52: 5 | R52: 10 | S52: 3 | T52: =_xlfn.XLOOKUP(Table1[[#This Row],[csat_score]],Sheet2!A:A,Sheet2!D:D) -> Alta | U52: =_xlfn.XLOOKUP(Table1[[#This Row],[nps_score]],Sheet2!B:B,Sheet2!E:E) -> promoter | V52: =_xlfn.XLOOKUP(Table1[[#This Row],[resolution_numeric]],Sheet2!C:C,Sheet2!F:F) -> yes | W52: =1 -> 1 | X52: =IF(ISBLANK(Table1[[#This Row],[nps_category]]),0,1) -> 1
A53: e9478ce7-e337-41fb-ac40-3cdac9feb543 | B53: 51985738333 | C53: 46139 | D53: RAG | E53: TRUE | F53: 2 | G53: 0.039583333 | H53: que info necesitas | I53: que info necesitas | J53: RAG | K53: TRUE | L53: FALSE | M53: 5.67355 | N53: 5 | O53: Juro que te amo | P53: 0.4681 | Q53: 5 | R53: 10 | S53: 2 | T53: =_xlfn.XLOOKUP(Table1[[#This Row],[csat_score]],Sheet2!A:A,Sheet2!D:D) -> Alta | U53: =_xlfn.XLOOKUP(Table1[[#This Row],[nps_score]],Sheet2!B:B,Sheet2!E:E) -> promoter | V53: =_xlfn.XLOOKUP(Table1[[#This Row],[resolution_numeric]],Sheet2!C:C,Sheet2!F:F) -> partial | W53: =1 -> 1 | X53: =IF(ISBLANK(Table1[[#This Row],[nps_category]]),0,1) -> 1
A54: e9478ce7-e337-41fb-ac40-3cdac9feb543 | B54: 51985738333 | C54: 46139 | D54: RAG | E54: TRUE | F54: 3 | G54: 0.048611111 | H54: Películas dramáticas emocionales | I54: Películas dramáticas emocionales | J54: RAG | K54: TRUE | L54: FALSE | M54: 9.1860667 | N54: 5 | O54: Sweetheart | P54: 0.2196 | Q54: 5 | R54: 10 | S54: 2 | T54: =_xlfn.XLOOKUP(Table1[[#This Row],[csat_score]],Sheet2!A:A,Sheet2!D:D) -> Alta | U54: =_xlfn.XLOOKUP(Table1[[#This Row],[nps_score]],Sheet2!B:B,Sheet2!E:E) -> promoter | V54: =_xlfn.XLOOKUP(Table1[[#This Row],[resolution_numeric]],Sheet2!C:C,Sheet2!F:F) -> partial | W54: =1 -> 1 | X54: =IF(ISBLANK(Table1[[#This Row],[nps_category]]),0,1) -> 1
A55: f5a4622b-7651-4ed2-a2db-4a16b01f5768 | B55: 57 316 7556912 | C55: 46139 | D55: DIRECT | E55: FALSE | F55: 1 | G55: 0.058333333 | H55: dame una serie parecida a friends | I55: dame una serie parecida a friends | J55: DIRECT | K55: FALSE | L55: FALSE | M55: 10.761933 | N55: 5 | O55: Mama Drama | P55: 0.5129 | Q55: 2 | R55: 10 | S55: 2 | T55: =_xlfn.XLOOKUP(Table1[[#This Row],[csat_score]],Sheet2!A:A,Sheet2!D:D) -> Baja | U55: =_xlfn.XLOOKUP(Table1[[#This Row],[nps_score]],Sheet2!B:B,Sheet2!E:E) -> promoter | V55: =_xlfn.XLOOKUP(Table1[[#This Row],[resolution_numeric]],Sheet2!C:C,Sheet2!F:F) -> partial | W55: =1 -> 1 | X55: =IF(ISBLANK(Table1[[#This Row],[nps_category]]),0,1) -> 1
A56: 5009b64e-830a-4ea2-8262-024f0632aa98 | B56: 57 316 7556912 | C56: 46140 | D56: RAG | E56: TRUE | F56: 1 | G56: 0.74166667 | H56: anime | I56: anime | J56: RAG | K56: TRUE | L56: FALSE | M56: 5.7222833 | N56: 5 | O56: Annie | P56: 0.4528 | Q56: 5 | R56: 10 | S56: 3 | T56: =_xlfn.XLOOKUP(Table1[[#This Row],[csat_score]],Sheet2!A:A,Sheet2!D:D) -> Alta | U56: =_xlfn.XLOOKUP(Table1[[#This Row],[nps_score]],Sheet2!B:B,Sheet2!E:E) -> promoter | V56: =_xlfn.XLOOKUP(Table1[[#This Row],[resolution_numeric]],Sheet2!C:C,Sheet2!F:F) -> yes | W56: =1 -> 1 | X56: =IF(ISBLANK(Table1[[#This Row],[nps_category]]),0,1) -> 1
A57: 7d7e081f-b306-4b87-9fe3-e0081a55db25 | B57: 57 316 7556912 | C57: 46140 | D57: RAG | E57: TRUE | F57: 1 | G57: 0.025 | H57: recomiendame algo del estilo de demon slayer | I57: recomiendame algo del estilo de demon slayer | J57: RAG | K57: TRUE | L57: FALSE | M57: 28.5125 | N57: 5 | O57: Demon Slayer: Kimetsu no Yaiba Infinity Castle | P57: 0.4608 | Q57: 5 | R57: 10 | S57: 3 | T57: =_xlfn.XLOOKUP(Table1[[#This Row],[csat_score]],Sheet2!A:A,Sheet2!D:D) -> Alta | U57: =_xlfn.XLOOKUP(Table1[[#This Row],[nps_score]],Sheet2!B:B,Sheet2!E:E) -> promoter | V57: =_xlfn.XLOOKUP(Table1[[#This Row],[resolution_numeric]],Sheet2!C:C,Sheet2!F:F) -> yes | W57: =1 -> 1 | X57: =IF(ISBLANK(Table1[[#This Row],[nps_category]]),0,1) -> 1
A58: d8c60a58-88c4-4612-9695-7b38273448d6 | B58: 57 316 7556912 | C58: 46140 | D58: DIRECT | E58: FALSE | F58: 1 | G58: 0.90694444 | H58: algo parecido a your name | I58: algo parecido a your name | J58: DIRECT | K58: FALSE | L58: FALSE | M58: 6.1042167 | N58: 5 | O58: We Are Who We Are | P58: 0.3933 | Q58: 5 | R58: 10 | S58: 3 | T58: =_xlfn.XLOOKUP(Table1[[#This Row],[csat_score]],Sheet2!A:A,Sheet2!D:D) -> Alta | U58: =_xlfn.XLOOKUP(Table1[[#This Row],[nps_score]],Sheet2!B:B,Sheet2!E:E) -> promoter | V58: =_xlfn.XLOOKUP(Table1[[#This Row],[resolution_numeric]],Sheet2!C:C,Sheet2!F:F) -> yes | W58: =1 -> 1 | X58: =IF(ISBLANK(Table1[[#This Row],[nps_category]]),0,1) -> 1
A59: 2464fa3c-3c02-4304-9012-3d02423ae1b0 | B59: 57 320 3286843 | C59: 46141 | D59: RAG | E59: TRUE | F59: 1 | G59: 0.82430556 | H59: peliculas de degeneracion humana | I59: peliculas de degeneracion humana | J59: RAG | K59: TRUE | L59: FALSE | M59: 10.300833 | N59: 5 | O59: Mama Drama | P59: 0.2242 | Q59: 5 | R59: 10 | S59: 2 | T59: =_xlfn.XLOOKUP(Table1[[#This Row],[csat_score]],Sheet2!A:A,Sheet2!D:D) -> Alta | U59: =_xlfn.XLOOKUP(Table1[[#This Row],[nps_score]],Sheet2!B:B,Sheet2!E:E) -> promoter | V59: =_xlfn.XLOOKUP(Table1[[#This Row],[resolution_numeric]],Sheet2!C:C,Sheet2!F:F) -> partial | W59: =1 -> 1 | X59: =IF(ISBLANK(Table1[[#This Row],[nps_category]]),0,1) -> 1
A60: 2464fa3c-3c02-4304-9012-3d02423ae1b0 | B60: 57 320 3286843 | C60: 46141 | D60: RAG | E60: TRUE | F60: 2 | G60: 0.83888889 | H60: dame entonces una recomendacion de peliculas de dictadores | I60: dame entonces una recomendacion de peliculas de dictadores | J60: RAG | K60: TRUE | L60: FALSE | M60: 9.25795 | N60: 5 | O60: Fenómenos | P60: 0.2066 | Q60: 5 | R60: 10 | S60: 2 | T60: =_xlfn.XLOOKUP(Table1[[#This Row],[csat_score]],Sheet2!A:A,Sheet2!D:D) -> Alta | U60: =_xlfn.XLOOKUP(Table1[[#This Row],[nps_score]],Sheet2!B:B,Sheet2!E:E) -> promoter | V60: =_xlfn.XLOOKUP(Table1[[#This Row],[resolution_numeric]],Sheet2!C:C,Sheet2!F:F) -> partial | W60: =1 -> 1 | X60: =IF(ISBLANK(Table1[[#This Row],[nps_category]]),0,1) -> 1
A61: 5b22a031-70f0-4090-877c-5d8436b15f04 | B61: 57 320 4638760 | C61: 46134 | D61: DIRECT | E61: FALSE | F61: 1 | G61: 0.059027778 | H61: Películas de ciencia ficción populares | I61: Películas de ciencia ficción populares | J61: DIRECT | K61: FALSE | L61: FALSE | M61: 23.229217 | N61: 5 | O61: Cristóbal Balenciaga | P61: 0.1195 | Q61: 5 | R61: 10 | S61: 3 | T61: =_xlfn.XLOOKUP(Table1[[#This Row],[csat_score]],Sheet2!A:A,Sheet2!D:D) -> Alta | U61: =_xlfn.XLOOKUP(Table1[[#This Row],[nps_score]],Sheet2!B:B,Sheet2!E:E) -> promoter | V61: =_xlfn.XLOOKUP(Table1[[#This Row],[resolution_numeric]],Sheet2!C:C,Sheet2!F:F) -> yes | W61: =1 -> 1 | X61: =IF(ISBLANK(Table1[[#This Row],[nps_category]]),0,1) -> 1
A62: 3223183e-56ba-4d14-b802-9ff82af15fab | B62: 57 318 8474215 | C62: 46141 | D62: RAG | E62: TRUE | F62: 3 | G62: 0.76597222 | H62: muchas gracias | I62: muchas gracias | J62: RAG | K62: TRUE | L62: FALSE | M62: 4.0001333 | N62: 5 | O62: A World of Ours | P62: 0.3414 | Q62: 5 | R62: 10 | S62: 2 | T62: =_xlfn.XLOOKUP(Table1[[#This Row],[csat_score]],Sheet2!A:A,Sheet2!D:D) -> Alta | U62: =_xlfn.XLOOKUP(Table1[[#This Row],[nps_score]],Sheet2!B:B,Sheet2!E:E) -> promoter | V62: =_xlfn.XLOOKUP(Table1[[#This Row],[resolution_numeric]],Sheet2!C:C,Sheet2!F:F) -> partial | W62: =1 -> 1 | X62: =IF(ISBLANK(Table1[[#This Row],[nps_category]]),0,1) -> 1
A63: 3fc204ab-0bf0-4e72-b4ce-c69dcff04760 | B63: 57 300 5179249 | C63: 46141 | D63: RAG | E63: TRUE | F63: 1 | G63: 0.83125 | H63: necesito ver algo sobre cine expresionista europeo de la segunda mitad de la primera mitad del siglo 20 toma como referente a personajes como murnau | I63: necesito ver algo sobre cine expresionista europeo de la segunda mitad de la primera mitad del siglo 20 toma como referente a personajes como murnau | J63: RAG | K63: TRUE | L63: FALSE | M63: 13.33515 | N63: 5 | O63: Illiterate | P63: 0.2903 | Q63: 3 | R63: 10 | S63: 2 | T63: =_xlfn.XLOOKUP(Table1[[#This Row],[csat_score]],Sheet2!A:A,Sheet2!D:D) -> Media | U63: =_xlfn.XLOOKUP(Table1[[#This Row],[nps_score]],Sheet2!B:B,Sheet2!E:E) -> promoter | V63: =_xlfn.XLOOKUP(Table1[[#This Row],[resolution_numeric]],Sheet2!C:C,Sheet2!F:F) -> partial | W63: =1 -> 1 | X63: =IF(ISBLANK(Table1[[#This Row],[nps_category]]),0,1) -> 1
A64: c0c52792-6615-4ca6-a249-3403be4294a0 | B64: 57 315 0717770 | C64: 46141 | D64: RAG | E64: TRUE | F64: 1 | G64: 0.87638889 | H64: peliculas animadas | I64: peliculas animadas | J64: RAG | K64: TRUE | L64: FALSE | M64: 4.9562167 | N64: 5 | O64: B-PROJECT | P64: 0.249 | Q64: 5 | R64: 10 | S64: 3 | T64: =_xlfn.XLOOKUP(Table1[[#This Row],[csat_score]],Sheet2!A:A,Sheet2!D:D) -> Alta | U64: =_xlfn.XLOOKUP(Table1[[#This Row],[nps_score]],Sheet2!B:B,Sheet2!E:E) -> promoter | V64: =_xlfn.XLOOKUP(Table1[[#This Row],[resolution_numeric]],Sheet2!C:C,Sheet2!F:F) -> yes | W64: =1 -> 1 | X64: =IF(ISBLANK(Table1[[#This Row],[nps_category]]),0,1) -> 1
A65: cdd8cdaf-9cd2-474f-95c4-01440caf608f | B65: 57 313 4595678 | C65: 46141 | D65: RAG | E65: TRUE | F65: 1 | G65: 0.95347222 | H65: Películas musicales populares | I65: Películas musicales populares | J65: RAG | K65: TRUE | L65: FALSE | M65: 14.289983 | N65: 5 | O65: Kally's Mashup | P65: 0.2836 | Q65: 3 | R65: 10 | S65: 2 | T65: =_xlfn.XLOOKUP(Table1[[#This Row],[csat_score]],Sheet2!A:A,Sheet2!D:D) -> Media | U65: =_xlfn.XLOOKUP(Table1[[#This Row],[nps_score]],Sheet2!B:B,Sheet2!E:E) -> promoter | V65: =_xlfn.XLOOKUP(Table1[[#This Row],[resolution_numeric]],Sheet2!C:C,Sheet2!F:F) -> partial | W65: =1 -> 1 | X65: =IF(ISBLANK(Table1[[#This Row],[nps_category]]),0,1) -> 1
A66: cdd8cdaf-9cd2-474f-95c4-01440caf608f | B66: 57 313 4595678 | C66: 46141 | D66: RAG | E66: TRUE | F66: 2 | G66: 0.98472222 | H66: rock | I66: rock | J66: RAG | K66: TRUE | L66: FALSE | M66: 15.277733 | N66: 5 | O66: Rocky | P66: 0.5218 | Q66: 3 | R66: 10 | S66: 2 | T66: =_xlfn.XLOOKUP(Table1[[#This Row],[csat_score]],Sheet2!A:A,Sheet2!D:D) -> Media | U66: =_xlfn.XLOOKUP(Table1[[#This Row],[nps_score]],Sheet2!B:B,Sheet2!E:E) -> promoter | V66: =_xlfn.XLOOKUP(Table1[[#This Row],[resolution_numeric]],Sheet2!C:C,Sheet2!F:F) -> partial | W66: =1 -> 1 | X66: =IF(ISBLANK(Table1[[#This Row],[nps_category]]),0,1) -> 1
... A69: 27f3ce91-1ed7-40b2-b25c-f66efcd5a9f9 | B69: 57 317 8517661 | C69: 46138 | D69: RAG | E69: TRUE | F69: 2 | G69: 0.99097222 | H69: Películas románticas emotivas | I69: Películas románticas emotivas | J69: RAG | K69: TRUE | L69: FALSE | M69: 10.0807 | N69: 5 | O69: Along came Love | P69: 0.2798 | Q69: 5 | R69: 10 | S69: 3 | T69: =_xlfn.XLOOKUP(Table1[[#This Row],[csat_score]],Sheet2!A:A,Sheet2!D:D) -> Alta | U69: =_xlfn.XLOOKUP(Table1[[#This Row],[nps_score]],Sheet2!B:B,Sheet2!E:E) -> promoter | V69: =_xlfn.XLOOKUP(Table1[[#This Row],[resolution_numeric]],Sheet2!C:C,Sheet2!F:F) -> yes | W69: =1 -> 1 | X69: =IF(ISBLANK(Table1[[#This Row],[nps_category]]),0,1) -> 1
A70: 2ac0bb83-8c2f-4993-83a5-3bc7c504acb3 | B70: 57 311 7259186 | C70: 46144 | D70: RAG | E70: TRUE | F70: 1 | G70: 0.12222222 | H70: acción con inteligencia artificial | I70: acción con inteligencia artificial | J70: RAG | K70: TRUE | L70: FALSE | M70: 5.32405 | N70: 5 | O70: Pantheon | P70: 0.3583 | Q70: =_xlfn.XLOOKUP(Table1[[#This Row],[session_id]],[1]chats_with_feedback!$A:$A,[1]chats_with_feedback!$F:$F) -> 3 | R70: =_xlfn.XLOOKUP(Table1[[#This Row],[session_id]],[1]chats_with_feedback!$A:$A,[1]chats_with_feedback!$G:$G) -> 7 | S70: =_xlfn.XLOOKUP(Table1[[#This Row],[session_id]],[1]chats_with_feedback!$A:$A,[1]chats_with_feedback!$J:$J) -> 2 | T70: =_xlfn.XLOOKUP(Table1[[#This Row],[csat_score]],Sheet2!A:A,Sheet2!D:D) -> Media | U70: =_xlfn.XLOOKUP(Table1[[#This Row],[nps_score]],Sheet2!B:B,Sheet2!E:E) -> passive | V70: =_xlfn.XLOOKUP(Table1[[#This Row],[resolution_numeric]],Sheet2!C:C,Sheet2!F:F) -> partial | W70: =1 -> 1 | X70: =IF(ISBLANK(Table1[[#This Row],[nps_category]]),0,1) -> 1
A71: 48b4ce6a-07fd-4434-b596-b32aec2cf5ad | B71: 57 314 6162072 | C71: 46134 | D71: RAG | E71: TRUE | F71: 1 | G71: 0.077083333 | H71: recomiendame una serie epica de alta sintonia | I71: recomiendame una serie epica de alta sintonia | J71: RAG | K71: TRUE | L71: FALSE | M71: 19.927133 | N71: 5 | O71: Il diario segreto di una minorenne | P71: 0.3411 | Q71: =_xlfn.XLOOKUP(Table1[[#This Row],[session_id]],[1]chats_with_feedback!$A:$A,[1]chats_with_feedback!$F:$F) -> 2 | R71: =_xlfn.XLOOKUP(Table1[[#This Row],[session_id]],[1]chats_with_feedback!$A:$A,[1]chats_with_feedback!$G:$G) -> 3 | S71: =_xlfn.XLOOKUP(Table1[[#This Row],[session_id]],[1]chats_with_feedback!$A:$A,[1]chats_with_feedback!$J:$J) -> 1 | T71: =_xlfn.XLOOKUP(Table1[[#This Row],[csat_score]],Sheet2!A:A,Sheet2!D:D) -> Baja | U71: =_xlfn.XLOOKUP(Table1[[#This Row],[nps_score]],Sheet2!B:B,Sheet2!E:E) -> detractor | V71: =_xlfn.XLOOKUP(Table1[[#This Row],[resolution_numeric]],Sheet2!C:C,Sheet2!F:F) -> no | W71: =1 -> 1 | X71: =IF(ISBLANK(Table1[[#This Row],[nps_category]]),0,1) -> 1
A72: 621f8839-f1d3-4d8d-a9cf-6287ce3ec223 | B72: 57 318 3707239 | C72: 46144 | D72: RAG | E72: TRUE | F72: 1 | G72: 0.17222222 | H72: acción con superhéroes | I72: acción con superhéroes | J72: RAG | K72: TRUE | L72: FALSE | M72: 5.1686667 | N72: 5 | O72: PJ Masks: Music Videos | P72: 0.3887 | Q72: =_xlfn.XLOOKUP(Table1[[#This Row],[session_id]],[1]chats_with_feedback!$A:$A,[1]chats_with_feedback!$F:$F) -> 3 | R72: =_xlfn.XLOOKUP(Table1[[#This Row],[session_id]],[1]chats_with_feedback!$A:$A,[1]chats_with_feedback!$G:$G) -> 7 | S72: =_xlfn.XLOOKUP(Table1[[#This Row],[session_id]],[1]chats_with_feedback!$A:$A,[1]chats_with_feedback!$J:$J) -> 2 | T72: =_xlfn.XLOOKUP(Table1[[#This Row],[csat_score]],Sheet2!A:A,Sheet2!D:D) -> Media | U72: =_xlfn.XLOOKUP(Table1[[#This Row],[nps_score]],Sheet2!B:B,Sheet2!E:E) -> passive | V72: =_xlfn.XLOOKUP(Table1[[#This Row],[resolution_numeric]],Sheet2!C:C,Sheet2!F:F) -> partial | W72: =1 -> 1 | X72: =IF(ISBLANK(Table1[[#This Row],[nps_category]]),0,1) -> 1
A73: c32fafa2-435e-402b-91c7-eb4e118a3020 | B73: 57 301 5989061 | C73: 46134 | D73: DIRECT | E73: FALSE | F73: 1 | G73: 0.049305556 | H73: una pelicula de ovnis y policias | I73: una pelicula de ovnis y policias | J73: DIRECT | K73: FALSE | L73: FALSE | M73: 17.86815 | N73: 5 | O73: Occident | P73: 0.1681 | Q73: =_xlfn.XLOOKUP(Table1[[#This Row],[session_id]],[1]chats_with_feedback!$A:$A,[1]chats_with_feedback!$F:$F) -> 2 | R73: =_xlfn.XLOOKUP(Table1[[#This Row],[session_id]],[1]chats_with_feedback!$A:$A,[1]chats_with_feedback!$G:$G) -> 3 | S73: =_xlfn.XLOOKUP(Table1[[#This Row],[session_id]],[1]chats_with_feedback!$A:$A,[1]chats_with_feedback!$J:$J) -> 1 | T73: =_xlfn.XLOOKUP(Table1[[#This Row],[csat_score]],Sheet2!A:A,Sheet2!D:D) -> Baja | U73: =_xlfn.XLOOKUP(Table1[[#This Row],[nps_score]],Sheet2!B:B,Sheet2!E:E) -> detractor | V73: =_xlfn.XLOOKUP(Table1[[#This Row],[resolution_numeric]],Sheet2!C:C,Sheet2!F:F) -> no | W73: =1 -> 1 | X73: =IF(ISBLANK(Table1[[#This Row],[nps_category]]),0,1) -> 1
A74: 1685093a-d39c-472d-aae2-f8c92886a91a | B74: 57 319 1760431 | C74: 46144 | D74: DIRECT | E74: FALSE | F74: 1 | G74: 0.14583333 | H74: ciencia ficción con aliens | I74: ciencia ficción con aliens | J74: DIRECT | K74: FALSE | L74: FALSE | M74: 3.8473 | N74: 5 | O74: Jeff and Some Aliens | P74: 0.4356 | Q74: =_xlfn.XLOOKUP(Table1[[#This Row],[session_id]],[1]chats_with_feedback!$A:$A,[1]chats_with_feedback!$F:$F) -> 5 | R74: =_xlfn.XLOOKUP(Table1[[#This Row],[session_id]],[1]chats_with_feedback!$A:$A,[1]chats_with_feedback!$G:$G) -> 10 | S74: =_xlfn.XLOOKUP(Table1[[#This Row],[session_id]],[1]chats_with_feedback!$A:$A,[1]chats_with_feedback!$J:$J) -> 3 | T74: =_xlfn.XLOOKUP(Table1[[#This Row],[csat_score]],Sheet2!A:A,Sheet2!D:D) -> Alta | U74: =_xlfn.XLOOKUP(Table1[[#This Row],[nps_score]],Sheet2!B:B,Sheet2!E:E) -> promoter | V74: =_xlfn.XLOOKUP(Table1[[#This Row],[resolution_numeric]],Sheet2!C:C,Sheet2!F:F) -> yes | W74: =1 -> 1 | X74: =IF(ISBLANK(Table1[[#This Row],[nps_category]]),0,1) -> 1
A75: f573224d-255c-4b19-8b1a-28adb0a3482b | B75: 57 313 7669392 | C75: 46134 | D75: RAG | E75: TRUE | F75: 1 | G75: 0.054861111 | H75: pelis sobre religion | I75: pelis sobre religion | J75: RAG | K75: TRUE | L75: FALSE | M75: 20.122083 | N75: 5 | O75: 3 Hati Dua Dunia Satu Cinta | P75: 0.1911 | Q75: =_xlfn.XLOOKUP(Table1[[#This Row],[session_id]],[1]chats_with_feedback!$A:$A,[1]chats_with_feedback!$F:$F) -> 2 | R75: =_xlfn.XLOOKUP(Table1[[#This Row],[session_id]],[1]chats_with_feedback!$A:$A,[1]chats_with_feedback!$G:$G) -> 3 | S75: =_xlfn.XLOOKUP(Table1[[#This Row],[session_id]],[1]chats_with_feedback!$A:$A,[1]chats_with_feedback!$J:$J) -> 1 | T75: =_xlfn.XLOOKUP(Table1[[#This Row],[csat_score]],Sheet2!A:A,Sheet2!D:D) -> Baja | U75: =_xlfn.XLOOKUP(Table1[[#This Row],[nps_score]],Sheet2!B:B,Sheet2!E:E) -> detractor | V75: =_xlfn.XLOOKUP(Table1[[#This Row],[resolution_numeric]],Sheet2!C:C,Sheet2!F:F) -> no | W75: =1 -> 1 | X75: =IF(ISBLANK(Table1[[#This Row],[nps_category]]),0,1) -> 1
A76: f573224d-255c-4b19-8b1a-28adb0a3482b | B76: 57 313 7669392 | C76: 46134 | D76: RAG | E76: TRUE | F76: 2 | G76: 0.090972222 | H76: pelis sobre aliens | I76: pelis sobre aliens | J76: RAG | K76: TRUE | L76: FALSE | M76: 31.171683 | N76: 5 | O76: 3Below: Tales of Arcadia | P76: 0.2409 | Q76: =_xlfn.XLOOKUP(Table1[[#This Row],[session_id]],[1]chats_with_feedback!$A:$A,[1]chats_with_feedback!$F:$F) -> 2 | R76: =_xlfn.XLOOKUP(Table1[[#This Row],[session_id]],[1]chats_with_feedback!$A:$A,[1]chats_with_feedback!$G:$G) -> 3 | S76: =_xlfn.XLOOKUP(Table1[[#This Row],[session_id]],[1]chats_with_feedback!$A:$A,[1]chats_with_feedback!$J:$J) -> 1 | T76: =_xlfn.XLOOKUP(Table1[[#This Row],[csat_score]],Sheet2!A:A,Sheet2!D:D) -> Baja | U76: =_xlfn.XLOOKUP(Table1[[#This Row],[nps_score]],Sheet2!B:B,Sheet2!E:E) -> detractor | V76: =_xlfn.XLOOKUP(Table1[[#This Row],[resolution_numeric]],Sheet2!C:C,Sheet2!F:F) -> no | W76: =1 -> 1 | X76: =IF(ISBLANK(Table1[[#This Row],[nps_category]]),0,1) -> 1
A77: f80997d9-ec4f-4af2-bf42-f05b7c98bd27 | B77: 57 313 0672562 | C77: 46144 | D77: DIRECT | E77: FALSE | F77: 1 | G77: 0.18611111 | H77: ciencia ficción futurista | I77: ciencia ficción futurista | J77: DIRECT | K77: FALSE | L77: FALSE | M77: 4.1307333 | N77: 5 | O77: Bureau 749 | P77: 0.3449 | Q77: =_xlfn.XLOOKUP(Table1[[#This Row],[session_id]],[1]chats_with_feedback!$A:$A,[1]chats_with_feedback!$F:$F) -> 3 | R77: =_xlfn.XLOOKUP(Table1[[#This Row],[session_id]],[1]chats_with_feedback!$A:$A,[1]chats_with_feedback!$G:$G) -> 7 | S77: =_xlfn.XLOOKUP(Table1[[#This Row],[session_id]],[1]chats_with_feedback!$A:$A,[1]chats_with_feedback!$J:$J) -> 2 | T77: =_xlfn.XLOOKUP(Table1[[#This Row],[csat_score]],Sheet2!A:A,Sheet2!D:D) -> Media | U77: =_xlfn.XLOOKUP(Table1[[#This Row],[nps_score]],Sheet2!B:B,Sheet2!E:E) -> passive | V77: =_xlfn.XLOOKUP(Table1[[#This Row],[resolution_numeric]],Sheet2!C:C,Sheet2!F:F) -> partial | W77: =1 -> 1 | X77: =IF(ISBLANK(Table1[[#This Row],[nps_category]]),0,1) -> 1
A78: c7bd6967-0349-4a3a-b098-668b108bfbae | B78: 57 317 5810492 | C78: 46144 | D78: RAG | E78: TRUE | F78: 1 | G78: 0.11180556 | H78: comedias familiares divertidas | I78: comedias familiares divertidas | J78: RAG | K78: TRUE | L78: FALSE | M78: 4.4047 | N78: 5 | O78: È questa la vita che sognavo da bambino? | P78: 0.1736 | Q78: =_xlfn.XLOOKUP(Table1[[#This Row],[session_id]],[1]chats_with_feedback!$A:$A,[1]chats_with_feedback!$F:$F) -> 2 | R78: =_xlfn.XLOOKUP(Table1[[#This Row],[session_id]],[1]chats_with_feedback!$A:$A,[1]chats_with_feedback!$G:$G) -> 3 | S78: =_xlfn.XLOOKUP(Table1[[#This Row],[session_id]],[1]chats_with_feedback!$A:$A,[1]chats_with_feedback!$J:$J) -> 1 | T78: =_xlfn.XLOOKUP(Table1[[#This Row],[csat_score]],Sheet2!A:A,Sheet2!D:D) -> Baja | U78: =_xlfn.XLOOKUP(Table1[[#This Row],[nps_score]],Sheet2!B:B,Sheet2!E:E) -> detractor | V78: =_xlfn.XLOOKUP(Table1[[#This Row],[resolution_numeric]],Sheet2!C:C,Sheet2!F:F) -> no | W78: =1 -> 1 | X78: =IF(ISBLANK(Table1[[#This Row],[nps_category]]),0,1) -> 1
A79: 4d99f7d0-65bd-486a-8652-6bdc169fb3a2 | B79: 57 313 4135614 | C79: 46144 | D79: RAG | E79: TRUE | F79: 1 | G79: 0.18125 | H79: comedias románticas ligeras | I79: comedias románticas ligeras | J79: RAG | K79: TRUE | L79: FALSE | M79: 3.8664 | N79: 5 | O79: Along came Love | P79: 0.2907 | Q79: =_xlfn.XLOOKUP(Table1[[#This Row],[session_id]],[1]chats_with_feedback!$A:$A,[1]chats_with_feedback!$F:$F) -> 3 | R79: =_xlfn.XLOOKUP(Table1[[#This Row],[session_id]],[1]chats_with_feedback!$A:$A,[1]chats_with_feedback!$G:$G) -> 7 | S79: =_xlfn.XLOOKUP(Table1[[#This Row],[session_id]],[1]chats_with_feedback!$A:$A,[1]chats_with_feedback!$J:$J) -> 2 | T79: =_xlfn.XLOOKUP(Table1[[#This Row],[csat_score]],Sheet2!A:A,Sheet2!D:D) -> Media | U79: =_xlfn.XLOOKUP(Table1[[#This Row],[nps_score]],Sheet2!B:B,Sheet2!E:E) -> passive | V79: =_xlfn.XLOOKUP(Table1[[#This Row],[resolution_numeric]],Sheet2!C:C,Sheet2!F:F) -> partial | W79: =1 -> 1 | X79: =IF(ISBLANK(Table1[[#This Row],[nps_category]]),0,1) -> 1
A80: af68ab28-0de6-4b6b-9173-8d013d17e19d | B80: 57 318 8069630 | C80: 46138 | D80: DIRECT | E80: FALSE | F80: 1 | G80: 0 | H80: me gustan las romanticas | I80: me gustan las romanticas | J80: DIRECT | K80: FALSE | L80: FALSE | M80: 2.8797 | N80: 5 | O80: Along came Love | P80: 0.2959 | Q80: =_xlfn.XLOOKUP(Table1[[#This Row],[session_id]],[1]chats_with_feedback!$A:$A,[1]chats_with_feedback!$F:$F) -> 3 | R80: =_xlfn.XLOOKUP(Table1[[#This Row],[session_id]],[1]chats_with_feedback!$A:$A,[1]chats_with_feedback!$G:$G) -> 7 | S80: =_xlfn.XLOOKUP(Table1[[#This Row],[session_id]],[1]chats_with_feedback!$A:$A,[1]chats_with_feedback!$J:$J) -> 2 | T80: =_xlfn.XLOOKUP(Table1[[#This Row],[csat_score]],Sheet2!A:A,Sheet2!D:D) -> Media | U80: =_xlfn.XLOOKUP(Table1[[#This Row],[nps_score]],Sheet2!B:B,Sheet2!E:E) -> passive | V80: =_xlfn.XLOOKUP(Table1[[#This Row],[resolution_numeric]],Sheet2!C:C,Sheet2!F:F) -> partial | W80: =1 -> 1 | X80: =IF(ISBLANK(Table1[[#This Row],[nps_category]]),0,1) -> 1
...

Sheet Sheet2
A1: csat_score | B1: nps_score | C1: resolution_numeric | D1: Valor original | E1: nps_category | F1: resolution_label
A2: 2 | B2: 3 | C2: 1 | D2: Baja | E2: detractor | F2: no
A3: 3 | B3: 7 | C3: 3 | D3: Media | E3: passive | F3: yes
A4: 5 | B4: 10 | C4: 2 | D4: Alta | E4: promoter | F4: partial
